Traceback (most recent call last):
  File "/Library/Frameworks/Python.framework/Versions/3.10/lib/python3.10/site-packages/jupyter_cache/executors/utils.py", line 58, in single_nb_execution
    executenb(
  File "/Library/Frameworks/Python.framework/Versions/3.10/lib/python3.10/site-packages/nbclient/client.py", line 1314, in execute
    return NotebookClient(nb=nb, resources=resources, km=km, **kwargs).execute()
  File "/Library/Frameworks/Python.framework/Versions/3.10/lib/python3.10/site-packages/jupyter_core/utils/__init__.py", line 165, in wrapped
    return loop.run_until_complete(inner)
  File "/Library/Frameworks/Python.framework/Versions/3.10/lib/python3.10/asyncio/base_events.py", line 649, in run_until_complete
    return future.result()
  File "/Library/Frameworks/Python.framework/Versions/3.10/lib/python3.10/site-packages/nbclient/client.py", line 709, in async_execute
    await self.async_execute_cell(
  File "/Library/Frameworks/Python.framework/Versions/3.10/lib/python3.10/site-packages/nbclient/client.py", line 1062, in async_execute_cell
    await self._check_raise_for_error(cell, cell_index, exec_reply)
  File "/Library/Frameworks/Python.framework/Versions/3.10/lib/python3.10/site-packages/nbclient/client.py", line 918, in _check_raise_for_error
    raise CellExecutionError.from_cell_and_msg(cell, exec_reply_content)
nbclient.exceptions.CellExecutionError: An error occurred while executing the following cell:
------------------
# Mit query nach dem Geschlechtscode
gender_codes = ["FEMALE", "MALE", "UNKNOWN"]
for i in range(len(request_urls)):
    for j in range(len(genders)):
        api_response = requests.get(request_urls[i], params={"gender": genders[j]})
        spokentext = api_response.text
        filename = f"{plays_selected[i]}_{genders[j]}.txt"
        filepath = os.path.join(output_dir, filename)
        with open(filepath, "w", encoding="utf-8") as file:
            file.write(spokentext)
------------------


[0;31m---------------------------------------------------------------------------[0m
[0;31mNameError[0m                                 Traceback (most recent call last)
Cell [0;32mIn[21], line 4[0m
[1;32m      2[0m gender_codes [38;5;241m=[39m [[38;5;124m"[39m[38;5;124mFEMALE[39m[38;5;124m"[39m, [38;5;124m"[39m[38;5;124mMALE[39m[38;5;124m"[39m, [38;5;124m"[39m[38;5;124mUNKNOWN[39m[38;5;124m"[39m]
[1;32m      3[0m [38;5;28;01mfor[39;00m i [38;5;129;01min[39;00m [38;5;28mrange[39m([38;5;28mlen[39m(request_urls)):
[0;32m----> 4[0m     [38;5;28;01mfor[39;00m j [38;5;129;01min[39;00m [38;5;28mrange[39m([38;5;28mlen[39m([43mgenders[49m)):
[1;32m      5[0m         api_response [38;5;241m=[39m requests[38;5;241m.[39mget(request_urls[i], params[38;5;241m=[39m{[38;5;124m"[39m[38;5;124mgender[39m[38;5;124m"[39m: genders[j]})
[1;32m      6[0m         spokentext [38;5;241m=[39m api_response[38;5;241m.[39mtext

[0;31mNameError[0m: name 'genders' is not defined

